Workbook
Name 매출상위3: _xludf.TAKE(_xll.xSORT(Data!$D$2:$D$11,1,-1),3)

Sheet 안내
A1: EGTools++ 호환 변환 테스트 샘플 — Excel 2021+ 신함수 전체
A3: 이 파일은 모던 Excel(동적배열)로 작성되어 신함수가 _xlfn./_xleta. 토큰으로 저장되어 있습니다.
A4: [새함수] 시트에 함수별 실제 수식(F열)과 원본 수식 텍스트(C열)가 있습니다.
A6: ■ 구버전 Excel(예: 2016 x86 + EGTools++)에서:
A7: 1) 열면 F열이 _xlfn.* 표시와 함께 #NAME? 오류로 보입니다.
A8: 2) 리본 [EGTools++] > [구버전 호환 적용] 실행 → 전 함수가 EGTools 함수명(bare/x접두)으로 바뀌고 계산됩니다.
A9: 3) [내장 함수로 복원]은 이 버전엔 네이티브가 없으므로 "변환할 대상이 없습니다"가 정상입니다.
A11: ■ 모던 Excel(2021/365 + EGTools++)에서:
A12: 1) 열면 전부 네이티브로 정상 계산됩니다(IMPORT 2종 제외 가능).
A13: 2) [구버전 호환 적용] → SORT/FILTER/LET은 xSORT/xFILTER/xLET로, GROUPBY/PIVOTBY 집계자는 "SUM"으로 변경.
A14: (문서가 구버전용으로 바뀌므로 이 상태에선 일부 #NAME? 표시가 정상입니다)
A15: 3) [내장 함수로 복원] → 전 함수가 네이티브로 재토큰화되어 다시 계산됩니다(IMAGE는 EG.IMAGE 유지).
... A19: ※ IMPORTTEXT/IMPORTCSV는 같은 폴더의 sample_import.csv를 읽습니다(365 네이티브는 2026 롤아웃).

Sheet 새함수
A1: 함수 | B1: 구분 | C1: 원본 수식(참고) | D1: 비고 | F1: 결과 →
A3: XLOOKUP | B3: 2021 | C3: =XLOOKUP(105,Data!A2:A11,Data!B2:B11) | D3: 사번 105 → 이름 | F3: =_xludf.XLOOKUP(105,Data!A2:A11,Data!B2:B11) -> #NAME?
A5: XMATCH | B5: 2021 | C5: =XMATCH(106,Data!A2:A11) | D5: 사번 106의 위치(6) | F5: =_xludf.XMATCH(106,Data!A2:A11) -> #NAME?
A7: FILTER | B7: 2021 | C7: =FILTER(Data!B2:B11,Data!C2:C11="영업") | D7: 호환 적용 시 xFILTER로 변환 | F7: {=_xll.xFILTER(Data!B2:B11,Data!C2:C11="영업")} -> #NAME?
F8: #NAME?
F9: #NAME?
F10: #NAME?
A12: SORT | B12: 2021 | C12: =SORT(Data!D2:D11,1,-1) | D12: 호환 적용 시 xSORT로 변환 | F12: {=_xll.xSORT(Data!D2:D11,1,-1)} -> #NAME?
F13: #NAME?
F14: #NAME?
F15: #NAME?
F16: #NAME?
F17: #NAME?
F18: #NAME?
F19: #NAME?
F20: #NAME?
F21: #NAME?
A23: SORTBY | B23: 2021 | C23: =SORTBY(Data!B2:B11,Data!D2:D11,-1) | D23: 매출 내림차순 이름 | F23: {=_xludf.SORTBY(Data!B2:B11,Data!D2:D11,-1)} -> #NAME?
F24: #NAME?
F25: #NAME?
F26: #NAME?
F27: #NAME?
F28: #NAME?
F29: #NAME?
F30: #NAME?
F31: #NAME?
F32: #NAME?
A34: UNIQUE | B34: 2021 | C34: =UNIQUE(Data!C2:C11) | D34: 부서 고유값 3종 | F34: {=_xludf.UNIQUE(Data!C2:C11)} -> #NAME?
F35: #NAME?
F36: #NAME?
A38: SEQUENCE | B38: 2021 | C38: =SEQUENCE(5) | D38: 1..5 | F38: {=_xludf.SEQUENCE(5)} -> #NAME?
F39: #NAME?
F40: #NAME?
F41: #NAME?
F42: #NAME?
A44: RANDARRAY | B44: 2021 | C44: =RANDARRAY(3,1,1,100,TRUE) | D44: 휘발성 — 열 때마다 값 변경 | F44: {=_xludf.RANDARRAY(3,1,1,100,TRUE)} -> #NAME?
F45: #NAME?
F46: #NAME?
A48: LET | B48: 2021 | C48: =LET(x,Data!D2:D11,SUM(x)/COUNT(x)) | D48: 호환 적용 시 xLET로 변환(평균 매출) | F48: =_xll.xLET(_xlpm.x,Data!D2:D11,SUM(_xlpm.x)/COUNT(_xlpm.x)) -> #NAME?
A50: TEXTSPLIT | B50: 2024/365 | C50: =TEXTSPLIT("사과,배,포도",",") | D50: 가로 3칸 분할 | F50: {=_xludf.TEXTSPLIT("사과,배,포도",",")} -> #NAME? | G50: #NAME? | H50: #NAME?
...

Sheet Data
A1: 사번 | B1: 이름 | C1: 부서 | D1: 매출 | E1: 지역 | G1: 10
A2: 101 | B2: 김민준 | C2: 영업 | D2: 1200 | E2: 서울 | G2: 20
A3: 102 | B3: 이서연 | C3: 개발 | D3: 950 | E3: 부산 | G3: 30
A4: 103 | B4: 박지훈 | C4: 영업 | D4: 800 | E4: 서울
A5: 104 | B5: 최수아 | C5: 기획 | D5: 1100 | E5: 부산
A6: 105 | B6: 정우진 | C6: 개발 | D6: 700 | E6: 서울
A7: 106 | B7: 강하은 | C7: 영업 | D7: 1500 | E7: 부산
A8: 107 | B8: 조현우 | C8: 기획 | D8: 600 | E8: 서울
A9: 108 | B9: 윤지민 | C9: 개발 | D9: 1300 | E9: 부산
A10: 109 | B10: 임서준 | C10: 영업 | D10: 900 | E10: 서울
A11: 110 | B11: 한예은 | C11: 기획 | D11: 1000 | E11: 부산
